Workbook

Sheet Enero_26
A1: Día | B1: fecha | C1: Turno | D1: Diaria | H1: Total
D2: Ingreso Diario | E2: Gasto Variable | F2: Gasto Fijo | G2: Ganancia Diaria | H2: Ingreso | I2: Gasto total | J2: Ganancia
A3: Jueves | B3: 46023 | C3: Mañana | G3: =D3-E3 -> 0 | H3: =D3+D4 -> 0 | I3: =E3+E4 -> 0 | J3: =H3-I3 -> 0 | K3: Año nuevo
C4: Tarde | G4: =D4-E4 -> 0
A5: Viernes | B5: 46024 | C5: Mañana | D5: 160143 | E5: 177825 | F5: 10000 | G5: =D5-E5 -> -17682 | H5: =D5+D6 -> 313366 | I5: =E5+E6+F5+F6 -> 288591 | J5: =H5-I5 -> 24775
C6: Tarde | D6: 153223 | E6: =40000+60766 -> 100766 | F6: 0 | G6: =D6-E6 -> 52457
A7: Sabado | B7: 46025 | C7: Mañana | D7: 167132 | E7: 0 | F7: 1064822 | G7: =D7-E7 -> 167132 | H7: =D7+D8 -> 416179 | I7: =E7+E8+F7+F8 -> 1064822 | J7: =H7-I7 -> -648643
C8: Tarde | D8: 249047 | E8: 0 | F8: 0 | G8: =D8-E8 -> 249047
A9: Lunes | B9: 46027 | C9: Mañana | D9: 249188 | E9: 296504 | F9: 0 | G9: =D9-E9 -> -47316 | H9: =D9+D10 -> 529898 | I9: =E9+E10+F9+F10 -> 384904 | J9: =H9-I9 -> 144994
C10: Tarde | D10: 280710 | E10: =55500+32900 -> 88400 | F10: 0 | G10: =D10-E10 -> 192310
A11: Martes | B11: 46028 | C11: Mañana | D11: 291821 | E11: =85800 -> 85800 | F11: 0 | G11: =D11-E11 -> 206021 | H11: =D11+D12 -> 534946 | I11: =E11+E12+F11+F12 -> 232418 | J11: =H11-I11 -> 302528
C12: Tarde | D12: 243125 | E12: =146618 -> 146618 | F12: 0 | G12: =D12-E12 -> 96507
A13: Miércoles | B13: 46029 | C13: Mañana | D13: 302341 | E13: =189382 -> 189382 | F13: 20000 | G13: =D13-E13 -> 112959 | H13: =D13+D14 -> 527236 | I13: =E13+E14+F13+F14 -> 416982 | J13: =H13-I13 -> 110254
C14: Tarde | D14: 224895 | E14: =79700+27500+29600+70800 -> 207600 | F14: 0 | G14: =D14-E14 -> 17295
A15: Jueves | B15: 46030 | C15: Mañana | D15: 375698 | E15: 15960 | F15: 0 | G15: =D15-E15 -> 359738 | H15: =D15+D16 -> 827120 | I15: =E15+E16+F15+F16 -> 15960 | J15: =H15-I15 -> 811160
C16: Tarde | D16: 451422 | E16: 0 | F16: 0 | G16: =D16-E16 -> 451422
A17: Viernes | B17: 46031 | C17: Mañana | D17: 332757 | E17: =214971 -> 214971 | F17: 50000 | G17: =D17-E17 -> 117786 | H17: =D17+D18 -> 729150 | I17: =E17+E18+F17+F18 -> 894971 | J17: =H17-I17 -> -165821 | K17: alquiler
C18: Tarde | D18: 396393 | E18: 0 | F18: =630000 -> 630000 | G18: =D18-E18 -> 396393
A19: Sabado | B19: 46032 | C19: Mañana | D19: 341627 | E19: 0 | F19: =50000 -> 50000 | G19: =D19-E19 -> 341627 | H19: =D19+D20 -> 513743 | I19: =E19+E20+F19+F20 -> 91000 | J19: =H19-I19 -> 422743
C20: Tarde | D20: 172116 | E20: 0 | F20: =41000 -> 41000 | G20: =D20-E20 -> 172116
A21: Lunes | B21: 46034 | C21: Mañana | D21: 166727 | E21: 292279 | F21: 15000 | G21: =D21-E21 -> -125552 | H21: =D21+D22 -> 315655 | I21: =E21+E22+F21+F22 -> 380845 | J21: =H21-I21 -> -65190
C22: Tarde | D22: 148928 | E22: 73566 | F22: 0 | G22: =D22-E22 -> 75362
A23: Martes | B23: 46035 | C23: Mañana | D23: 289099 | E23: =71000+12000+147000 -> 230000 | F23: 0 | G23: =D23-E23 -> 59099 | H23: =D23+D24 -> 757044 | I23: =E23+E24+F23+F24 -> 482900 | J23: =H23-I23 -> 274144
C24: Tarde | D24: 467945 | E24: =194600+20900+37400 -> 252900 | F24: 0 | G24: =D24-E24 -> 215045
A25: Miércoles | B25: 46036 | C25: Mañana | D25: 190739 | E25: 234578 | F25: 30000 | G25: =D25-E25 -> -43839 | H25: =D25+D26 -> 420681 | I25: =E25+E26+F25+F26 -> 264578 | J25: =H25-I25 -> 156103
C26: Tarde | D26: 229942 | E26: 0 | F26: 0 | G26: =D26-E26 -> 229942
A27: Jueves | B27: 46037 | C27: Mañana | D27: 160207 | E27: =70800+50290 -> 121090 | F27: 0 | G27: =D27-E27 -> 39117 | H27: =D27+D28 -> 375059 | I27: =E27+E28+F27+F28 -> 195963 | J27: =H27-I27 -> 179096
C28: Tarde | D28: 214852 | E28: =74873 -> 74873 | F28: 0 | G28: =D28-E28 -> 139979
A29: Viernes | B29: 46038 | C29: Mañana | D29: 224757 | E29: 327395 | F29: 10000 | G29: =D29-E29 -> -102638 | H29: =D29+D30 -> 471444 | I29: =E29+E30+F29+F30 -> 411395 | J29: =H29-I29 -> 60049
C30: Tarde | D30: 246687 | E30: 54000 | F30: 20000 | G30: =D30-E30 -> 192687
A31: Sabado | B31: 46039 | C31: Mañana | D31: 137650 | E31: 0 | F31: 1202781 | G31: =D31-E31 -> 137650 | H31: =D31+D32 -> 363632 | I31: =E31+E32+F31+F32 -> 1202781 | J31: =H31-I31 -> -839149
C32: tarde | D32: 225982 | E32: 0 | F32: 0 | G32: =D32-E32 -> 225982 | U32: sabado normal
A33: Lunes | B33: 46041 | C33: Mañana | D33: 233113 | E33: =72534 -> 72534 | F33: 0 | G33: =D33-E33 -> 160579 | H33: =D33+D34 -> 355934 | I33: =E33+E34+F33+F34 -> 229593 | J33: =H33-I33 -> 126341 | U33: pago sueldos
C34: Tarde | D34: 122821 | E34: =157059 -> 157059 | F34: 0 | G34: =D34-E34 -> -34238
A35: Martes | B35: 46042 | C35: Mañana | D35: 199867 | E35: 123480 | F35: 0 | G35: =D35-E35 -> 76387 | H35: =D35+D36 -> 497953 | I35: =E35+E36+F35+F36 -> 206180 | J35: =H35-I35 -> 291773
C36: Tarde | D36: 298086 | E36: =19200+63500 -> 82700 | F36: 0 | G36: =D36-E36 -> 215386
A37: Miércoles | B37: 46043 | C37: Mañana | D37: 168239 | E37: =42389+168049 -> 210438 | F37: 0 | G37: =D37-E37 -> -42199 | H37: =D37+D38 -> 356109 | I37: =E37+E38+F37+F38 -> 422990 | J37: =H37-I37 -> -66881
C38: Tarde | D38: 187870 | E38: =65952+146600 -> 212552 | F38: 0 | G38: =D38-E38 -> -24682
A39: Jueves | B39: 46044 | C39: Mañana | D39: 186682 | E39: 46430 | F39: 0 | G39: =D39-E39 -> 140252 | H39: =D39+D40 -> 349482 | I39: =E39+E40+F39+F40 -> 71830 | J39: =H39-I39 -> 277652
C40: Tarde | D40: 162800 | E40: 25400 | F40: 0 | G40: =D40-E40 -> 137400
...

Sheet Febrero_26
A1: Día | B1: fecha | C1: Turno | D1: Diaria | H1: Total
D2: Ingreso Diario | E2: Gasto Variable | F2: Gasto Fijo | G2: Ganancia Diaria | H2: Ingreso | I2: Gasto total | J2: Ganancia
A3: Lunes | B3: 46055 | C3: Mañana | D3: 209865 | E3: 233452 | F3: 0 | G3: =D3-E3-F3 -> -23587 | H3: =D3+D4 -> 525840 | I3: =E3+E4+F3+F4 -> 233452 | J3: =H3-I3 -> 292388
C4: Tarde | D4: 315975 | E4: 0 | F4: 0 | G4: =D4-E4-F4 -> 315975
A5: Martes | B5: 46056 | C5: Mañana | D5: 349390 | E5: =88413+21000+88181+88800 -> 286394 | F5: 0 | G5: =D5-E5-F5 -> 62996 | H5: =D5+D6 -> 724147 | I5: =E5+E6+F5+F6 -> 634494 | J5: =H5-I5 -> 89653
C6: Tarde | D6: 374757 | E6: =212700+35400 -> 248100 | F6: 100000 | G6: =D6-E6-F6 -> 26657
A7: Miércoles | B7: 46057 | C7: Mañana | D7: 466921 | E7: 245164 | F7: 0 | G7: =D7-E7-F7 -> 221757 | H7: =D7+D8 -> 819228 | I7: =E7+E8+F7+F8 -> 745164 | J7: =H7-I7 -> 74064
C8: Tarde | D8: 352307 | E8: 0 | F8: 500000 | G8: =D8-E8-F8 -> -147693
A9: Jueves | B9: 46058 | C9: Mañana | D9: 395389 | E9: =79078+40269+57080+26200 -> 202627 | F9: 0 | G9: =D9-E9-F9 -> 192762 | H9: =D9+D10 -> 905031 | I9: =E9+E10+F9+F10 -> 349246 | J9: =H9-I9 -> 555785
C10: Tarde | D10: 509642 | E10: 146619 | F10: 0 | G10: =D10-E10-F10 -> 363023
A11: Viernes | B11: 46059 | C11: Mañana | D11: 366147 | E11: =353496 -> 353496 | F11: 0 | G11: =D11-E11-F11 -> 12651 | H11: =D11+D12 -> 769716 | I11: =E11+E12+F11+F12 -> 557746 | J11: =H11-I11 -> 211970
C12: Tarde | D12: 403569 | E12: =54250 -> 54250 | F12: 150000 | G12: =D12-E12-F12 -> 199319
A13: Sabado | B13: 46060 | C13: Mañana | D13: 173311 | E13: 37000 | F13: =30000+32000+8000+154000 -> 224000 | G13: =D13-E13-F13 -> -87689 | H13: =D13+D14 -> 337095 | I13: =E13+E14+F13+F14 -> 371000 | J13: =H13-I13 -> -33905
C14: Tarde | D14: 163784 | E14: 0 | F14: =80000+30000 -> 110000 | G14: =D14-E14-F14 -> 53784
A15: Lunes | B15: 46062 | C15: Mañana | D15: 321486 | E15: =158343 -> 158343 | F15: =82000 -> 82000 | G15: =D15-E15-F15 -> 81143 | H15: =D15+D16 -> 655625 | I15: =E15+E16+F15+F16 -> 290612 | J15: =H15-I15 -> 365013
C16: Tarde | D16: 334139 | E16: 40269 | F16: 10000 | G16: =D16-E16-F16 -> 283870
A17: Martes | B17: 46063 | C17: Mañana | D17: 233300 | E17: =22757 -> 22757 | F17: 710000 | G17: =D17-E17-F17 -> -499457 | H17: =D17+D18 -> 488803 | I17: =E17+E18+F17+F18 -> 760757 | J17: =H17-I17 -> -271954 | K17: alquiler
C18: Tarde | D18: 255503 | E18: 28000 | F18: 0 | G18: =D18-E18-F18 -> 227503
A19: Miércoles | B19: 46064 | C19: Mañana | D19: 376331 | E19: =231404+35005 -> 266409 | F19: =30000+4000 -> 34000 | G19: =D19-E19-F19 -> 75922 | H19: =D19+D20 -> 729967 | I19: =E19+E20+F19+F20 -> 527627 | J19: =H19-I19 -> 202340
C20: Tarde | D20: 353636 | E20: =67118+5100 -> 72218 | F20: 155000 | G20: =D20-E20-F20 -> 126418
A21: Jueves | B21: 46065 | C21: Mañana | D21: 412698 | E21: =45843+59150+6500 -> 111493 | F21: 20000 | G21: =D21-E21-F21 -> 281205 | H21: =D21+D22 -> 703439 | I21: =E21+E22+F21+F22 -> 475493 | J21: =H21-I21 -> 227946
C22: Tarde | D22: 290741 | E22: =147000+20000 -> 167000 | F22: =30000+147000 -> 177000 | G22: =D22-E22-F22 -> -53259 | K22: Plata real
A23: Viernes | B23: 46066 | C23: Mañana | D23: 489696 | E23: =61000+71260+188200 -> 320460 | F23: 0 | G23: =D23-E23-F23 -> 169236 | H23: =D23+D24 -> 913537 | I23: =E23+E24+F23+F24 -> 764899 | J23: =H23-I23 -> 148638 | K23: 860000
C24: Tarde | D24: 423841 | E24: =264170+40269 -> 304439 | F24: 140000 | G24: =D24-E24-F24 -> -20598
A25: Sabado | B25: 46067 | C25: Mañana | D25: 172042 | E25: =13900 -> 13900 | F25: 877133 | G25: =D25-E25-F25 -> -718991 | H25: =D25+D26 -> 412184 | I25: =E25+E26+F25+F26 -> 909033 | J25: =H25-I25 -> -496849 | K25: =290000+184000+190000 -> 664000
C26: tarde | D26: 240142 | E26: 0 | F26: 18000 | G26: =D26-E26-F26 -> 222142 | U26: sabado normal
A27: Lunes | B27: 46069 | C27: Mañana | G27: =D27-E27-F27 -> 0 | H27: =D27+D28 -> 0 | I27: =E27+E28+F27+F28 -> 0 | J27: =H27-I27 -> 0 | K27: Feriado | U27: pago sueldos
C28: Tarde | G28: =D28-E28-F28 -> 0
A29: Martes | B29: 46070 | C29: Mañana | G29: =D29-E29-F29 -> 0 | H29: =D29+D30 -> 0 | I29: =E29+E30+F29+F30 -> 0 | J29: =H29-I29 -> 0
C30: Tarde | G30: =D30-E30-F30 -> 0
A31: Miércoles | B31: 46071 | C31: Mañana | G31: =D31-E31-F31 -> 0 | H31: =D31+D32 -> 0 | I31: =E31+E32+F31+F32 -> 0 | J31: =H31-I31 -> 0
C32: Tarde | G32: =D32-E32-F32 -> 0
A33: Jueves | B33: 46072 | C33: Mañana | G33: =D33-E33-F33 -> 0 | H33: =D33+D34 -> 0 | I33: =E33+E34+F33+F34 -> 0 | J33: =H33-I33 -> 0
C34: Tarde | G34: =D34-E34-F34 -> 0
A35: Viernes | B35: 46073 | C35: Mañana | G35: =D35-E35-F35 -> 0 | H35: =D35+D36 -> 0 | I35: =E35+E36+F35+F36 -> 0 | J35: =H35-I35 -> 0
C36: Tarde | G36: =D36-E36-F36 -> 0 | Q36: Sueldo Xime
A37: Sabado | B37: 46074 | C37: Mañana | G37: =D37-E37-F37 -> 0 | H37: =D37+D38 -> 0 | I37: =E37+E38+F37+F38 -> 0 | J37: =H37-I37 -> 0 | N37: Ingreso | O37: 1 | Q37: Dia | R37: Monto | T37: Total
C38: tarde | G38: =D38-E38-F38 -> 0 | N38: Gasto | O38: =I51*100/H51/100 -> 0.82903502 | Q38: 46055 | R38: 100000 | T38: =SUM(R38:R45) -> 1429000
A39: Lunes | B39: 46076 | C39: Mañana | G39: =D39-E39-F39 -> 0 | H39: =D39+D40 -> 0 | I39: =E39+E40+F39+F40 -> 0 | J39: =H39-I39 -> 0 | N39: Ganancia | O39: =(100%-O38) -> 0.17096498 | Q39: 46057 | R39: 500000
C40: Tarde | G40: =D40-E40-F40 -> 0 | Q40: 46059 | R40: 150000
...

Sheet Cash_2026
A1: Mes | B1: Enero | C1: Febrero | D1: Marzo | E1: Abril | F1: Mayo | G1: Junio | H1: Julio | I1: Agosto | J1: Septiembre | K1: Octubre | L1: Noviembre | M1: Diciembre
A2: Ingreso | B2: =Enero_26!H57 -> 12780932 | C2: =Febrero_26!H51 -> 7984612
A3: Gasto | B3: =Enero_26!I57 -> 9651752 | C3: =Febrero_26!I51 -> 6619523
A4: Ganancia | B4: =Enero_26!J57 -> 3129180 | C4: =Febrero_26!J51 -> 1365089
A24: Mes | B24: Ingreso | C24: Ganancia | D24: Porcentaje
A25: Enero | B25: =B2 -> 12780932 | C25: =B4 -> 3129180 | D25: =(C25*100/B25)/100 -> 0.24483191
A26: Febrero | D26: =(C26*100/B26)/100 -> #DIV/0!
A27: Marzo | D27: =(C27*100/B27)/100 -> #DIV/0!
A28: Abril | D28: =(C28*100/B28)/100 -> #DIV/0!
A29: Mayo | D29: =(C29*100/B29)/100 -> #DIV/0!
A30: Junio | D30: =(C30*100/B30)/100 -> #DIV/0!
A31: Julio | D31: =(C31*100/B31)/100 -> #DIV/0!
A32: Agosto | D32: =(C32*100/B32)/100 -> #DIV/0!
A33: Septiembre | D33: =(C33*100/B33)/100 -> #DIV/0!
A34: Octubre | D34: =(C34*100/B34)/100 -> #DIV/0!
A35: Noviembre | D35: =(C35*100/B35)/100 -> #DIV/0!
A36: Diciembre | D36: =(C36*100/B36)/100 -> #DIV/0!
A37: Promedio | B37: =AVERAGEA(B25:B36) -> 12780932 | C37: =AVERAGEA(C25:C36) -> 3129180 | D37: =AVERAGEA(D25:D36) -> #DIV/0!
E40: Rangos Porcentaje | G40: Estado | H40: Color
E41: 0 - 35 % | G41: Malo
E42: 35.1 - 39.5 % | G42: Regular
E43: 39.6 - 100% | G43: Bueno

Sheet Cash_2025
A1: Mes | B1: Enero | C1: Febrero | D1: Marzo | E1: Abril | F1: Mayo | G1: Junio | H1: Julio | I1: Agosto | J1: Septiembre | K1: Octubre | L1: Noviembre | M1: Diciembre
A2: Ingreso | B2: 10287446 | C2: 16394489 | D2: 19438482 | E2: 24103384 | F2: 25255179 | G2: 22712881 | H2: 17905501 | I2: 22131598 | J2: 21336631 | K2: 22846807 | L2: 17439857 | M2: 15577506
A3: Gasto | B3: 7130047 | C3: 10442183 | D3: 11713691 | E3: 14982902 | F3: 14083777 | G3: 14858214 | H3: 10150223 | I3: 14790380 | J3: 13756509 | K3: 13850929 | L3: 9247295 | M3: 9725418
A4: Ganancia | B4: 3157399 | C4: 5952306 | D4: 7724791 | E4: 9120482 | F4: 11171402 | G4: 7854667 | H4: 7755278 | I4: 7341218 | J4: 7580122 | K4: 8995878 | L4: 8192562 | M4: 5852088
A24: Mes | B24: Ingreso | C24: Ganancia | D24: Porcentaje
A25: Enero | B25: 10287446 | C25: 3157399 | D25: =(C25*100/B25)/100 -> 0.30691767
A26: Febrero | B26: 16394489 | C26: 5952306 | D26: =(C26*100/B26)/100 -> 0.36306749
A27: Marzo | B27: 19438482 | C27: 7724791 | D27: =(C27*100/B27)/100 -> 0.39739682
A28: Abril | B28: 24103384 | C28: 9120482 | D28: =(C28*100/B28)/100 -> 0.3783901
A29: Mayo | B29: 25255179 | C29: 11171402 | D29: =(C29*100/B29)/100 -> 0.44234103
A30: Junio | B30: 22712881 | C30: 7854667 | D30: =(C30*100/B30)/100 -> 0.34582434
A31: Julio | B31: 17905501 | C31: 7755278 | D31: =(C31*100/B31)/100 -> 0.43312265
A32: Agosto | B32: 22131598 | C32: 7341218 | D32: =(C32*100/B32)/100 -> 0.33170754
A33: Septiembre | B33: 21336631 | C33: 7580122 | D33: =(C33*100/B33)/100 -> 0.3552633
A34: Octubre | B34: 22846807 | C34: 8995878 | D34: =(C34*100/B34)/100 -> 0.39374771
A35: Noviembre | B35: 17439857 | C35: 8192562 | D35: =(C35*100/B35)/100 -> 0.46976085
A36: Diciembre | B36: 15577506 | C36: 5852088 | D36: =(C36*100/B36)/100 -> 0.37567554
A37: Promedio | B37: =AVERAGEA(B25:B36) -> 19619147 | C37: =AVERAGEA(C25:C36) -> 7558182.8 | D37: =AVERAGEA(D25:D36) -> 0.38276792
E40: Rangos Porcentaje | G40: Estado | H40: Color
E41: 0 - 35 % | G41: Malo
E42: 35.1 - 39.5 % | G42: Regular
E43: 39.6 - 100% | G43: Bueno

Sheet Febrero
A1: Día | B1: fecha | C1: Turno | D1: Diaria | G1: Total
D2: Ingreso Diario | E2: Gasto Diario | F2: Ganancia Diaria | G2: Ingreso | H2: Gasto | I2: Ganancia
A3: Sabado | B3: 45689 | C3: Mañana | D3: 142423 | E3: 300000 | F3: =D3-E3 -> -157577 | G3: =D3+D4 -> 318646 | H3: =E3+E4 -> 688525 | I3: =G3-H3 -> -369879
C4: Tarde | D4: 176223 | E4: 388525 | F4: =D4-E4 -> -212302
A5: Lunes | B5: 45691 | C5: Mañana | D5: 150615 | E5: =46200+12100+14000 -> 72300 | F5: =D5-E5 -> 78315 | G5: =D5+D6 -> 457375 | H5: =E5+E6 -> 243714 | I5: =G5-H5 -> 213661
C6: Tarde | D6: 306760 | E6: 171414 | F6: =D6-E6 -> 135346
A7: Martes | B7: 45692 | C7: Mañana | D7: 250873 | E7: =57861+9000+27000 -> 93861 | F7: =D7-E7 -> 157012 | G7: =D7+D8 -> 561223 | H7: =E7+E8 -> 131484 | I7: =G7-H7 -> 429739
C8: Tarde | D8: 310350 | E8: =9000+28623 -> 37623 | F8: =D8-E8 -> 272727
A9: Miércoles | B9: 45693 | C9: Mañana | D9: 351229 | E9: =26400+13000+12700+48770+18798+102300+51885+7000 -> 280853 | F9: =D9-E9 -> 70376 | G9: =D9+D10 -> 580881 | H9: =E9+E10 -> 481584 | I9: =G9-H9 -> 99297
C10: Tarde | D10: 229652 | E10: =41568+50000+74660+24503+10000 -> 200731 | F10: =D10-E10 -> 28921
A11: Jueves | B11: 45694 | C11: Mañana | D11: 320291 | E11: =123000+117136+88757 -> 328893 | F11: =D11-E11 -> -8602 | G11: =D11+D12 -> 541892 | H11: =E11+E12 -> 537996 | I11: =G11-H11 -> 3896
C12: Tarde | D12: 221601 | E12: =90000+9000+16800+15000+18900+22500+29403+7500 -> 209103 | F12: =D12-E12 -> 12498
A13: Viernes | B13: 45695 | C13: Mañana | D13: 278718 | E13: =15850 -> 15850 | F13: =D13-E13 -> 262868 | G13: =D13+D14 -> 556568 | H13: =E13+E14 -> 50950 | I13: =G13-H13 -> 505618
C14: Tarde | D14: 277850 | E14: =35100 -> 35100 | F14: =D14-E14 -> 242750
A15: Sabado | B15: 45696 | C15: Mañana | D15: 218916 | E15: =40000 -> 40000 | F15: =D15-E15 -> 178916 | G15: =D15+D16 -> 287916 | H15: =E15+E16 -> 40000 | I15: =G15-H15 -> 247916
C16: Tarde | D16: 69000 | E16: 0 | F16: =D16-E16 -> 69000
A17: Lunes | B17: 45698 | C17: Mañana | D17: 293598 | E17: =50944+12000+16850+32000 -> 111794 | F17: =D17-E17 -> 181804 | G17: =D17+D18 -> 556895 | H17: =E17+E18 -> 799882 | I17: =G17-H17 -> -242987 | J17: alquiler
C18: Tarde | D18: 263297 | E18: =119100+9000+109988+450000 -> 688088 | F18: =D18-E18 -> -424791
A19: Martes | B19: 45699 | C19: Mañana | D19: 441910 | E19: =12000+17700+108800+43626+7000 -> 189126 | F19: =D19-E19 -> 252784 | G19: =D19+D20 -> 804760 | H19: =E19+E20 -> 368476 | I19: =G19-H19 -> 436284
C20: Tarde | D20: 362850 | E20: =7000+58500+40000+34050+19800+20000 -> 179350 | F20: =D20-E20 -> 183500
A21: Miércoles | B21: 45700 | C21: Mañana | D21: 443564 | E21: =16000+7500+45000+122035+50943+26400+16200+81350 -> 365428 | F21: =D21-E21 -> 78136 | G21: =D21+D22 -> 680198 | H21: =E21+E22 -> 676585 | I21: =G21-H21 -> 3613
C22: Tarde | D22: 236634 | E22: =191157+80000+40000 -> 311157 | F22: =D22-E22 -> -74523
A23: Jueves | B23: 45701 | C23: Mañana | D23: 420470 | E23: =148349 -> 148349 | F23: =D23-E23 -> 272121 | G23: =D23+D24 -> 811644 | H23: =E23+E24 -> 235743 | I23: =G23-H23 -> 575901
C24: Tarde | D24: 391174 | E24: =30000+15000+22394+20000 -> 87394 | F24: =D24-E24 -> 303780
A25: Viernes | B25: 45702 | C25: Mañana | D25: 454813 | E25: =15000+10600+12000+41370+321129 -> 400099 | F25: =D25-E25 -> 54714 | G25: =D25+D26 -> 821597 | H25: =E25+E26 -> 514981 | I25: =G25-H25 -> 306616
C26: Tarde | D26: 366784 | E26: =53100+44350+17432 -> 114882 | F26: =D26-E26 -> 251902
A27: Sabado | B27: 45703 | C27: Mañana | D27: 238025 | E27: =43200+13200 -> 56400 | F27: =D27-E27 -> 181625 | G27: =D27+D28 -> 513525 | H27: =E27+E28 -> 726985 | I27: =G27-H27 -> -213460
C28: tarde | D28: 275500 | E28: =670585 -> 670585 | F28: =D28-E28 -> -395085 | T28: sabado normal
A29: Lunes | B29: 45705 | C29: Mañana | D29: 429456 | E29: =173175+91800+19100 -> 284075 | F29: =D29-E29 -> 145381 | G29: =D29+D30 -> 809993 | H29: =E29+E30 -> 313075 | I29: =G29-H29 -> 496918 | T29: pago sueldos
C30: Tarde | D30: 380537 | E30: =12000+9000+8000 -> 29000 | F30: =D30-E30 -> 351537
A31: Martes | B31: 45706 | C31: Mañana | D31: 369568 | E31: =17750+16800+115560+66600 -> 216710 | F31: =D31-E31 -> 152858 | G31: =D31+D32 -> 670475 | H31: =E31+E32 -> 442247 | I31: =G31-H31 -> 228228
C32: Tarde | D32: 300907 | E32: =48000+177537 -> 225537 | F32: =D32-E32 -> 75370
A33: Miércoles | B33: 45707 | C33: Mañana | D33: 556190 | E33: =13200+109100+9000+26400+123000 -> 280700 | F33: =D33-E33 -> 275490 | G33: =D33+D34 -> 802998 | H33: =E33+E34 -> 551026 | I33: =G33-H33 -> 251972
C34: Tarde | D34: 246808 | E34: =270326 -> 270326 | F34: =D34-E34 -> -23518
A35: Jueves | B35: 45708 | C35: Mañana | D35: 459311 | E35: =43656+31500+19100+30000 -> 124256 | F35: =D35-E35 -> 335055 | G35: =D35+D36 -> 787785 | H35: =E35+E36 -> 401433 | I35: =G35-H35 -> 386352
C36: Tarde | D36: 328474 | E36: =277177 -> 277177 | F36: =D36-E36 -> 51297
A37: Viernes | B37: 45709 | C37: Mañana | D37: 515309 | E37: =53448+78800+86870+33600+9000+36860+9000 -> 307578 | F37: =D37-E37 -> 207731 | G37: =D37+D38 -> 878709 | H37: =E37+E38 -> 515551 | I37: =G37-H37 -> 363158
C38: Tarde | D38: 363400 | E38: =167973+40000 -> 207973 | F38: =D38-E38 -> 155427
A39: Sabado | B39: 45710 | C39: Mañana | D39: 202897 | E39: =11000+19800 -> 30800 | F39: =D39-E39 -> 172097 | G39: =D39+D40 -> 367407 | H39: =E39+E40 -> 53690 | I39: =G39-H39 -> 313717 | M39: Ingreso | N39: 1
C40: tarde | D40: 164510 | E40: =22890 -> 22890 | F40: =D40-E40 -> 141620 | M40: Gasto | N40: =H51*100/G51/100 -> 0.63693251
...

Sheet Marzo
A1: Día | B1: fecha | C1: Turno | D1: Diaria | G1: Total
D2: Ingreso Diario | E2: Gasto Diario | F2: Ganancia Diaria | G2: Ingreso | H2: Gasto | I2: Ganancia
A3: Sabado | B3: 45717 | C3: Mañana | D3: 237384 | E3: =11850+46350 -> 58200 | F3: =D3-E3 -> 179184 | G3: =D3+D4 -> 509407 | H3: =E3+E4 -> 675705 | I3: =G3-H3 -> -166298
C4: Tarde | D4: 272023 | E4: 617505 | F4: =D4-E4 -> -345482
A5: Miércoles | B5: 45721 | C5: Mañana | D5: 341720 | E5: =45600+15150+17414+50081+26400+13000+117000+18000 -> 302645 | F5: =D5-E5 -> 39075 | G5: =D5+D6 -> 627372 | H5: =E5+E6 -> 565143 | I5: =G5-H5 -> 62229
C6: Tarde | D6: 285652 | E6: =262498 -> 262498 | F6: =D6-E6 -> 23154
A7: Jueves | B7: 45722 | C7: Mañana | D7: 463100 | E7: =47500+11600+53448+29610+11400 -> 153558 | F7: =D7-E7 -> 309542 | G7: =D7+D8 -> 822203 | H7: =E7+E8 -> 392377 | I7: =G7-H7 -> 429826
C8: Tarde | D8: 359103 | E8: =238819 -> 238819 | F8: =D8-E8 -> 120284
A9: Viernes | B9: 45723 | C9: Mañana | D9: 517437 | E9: =12300+78800+30000 -> 121100 | F9: =D9-E9 -> 396337 | G9: =D9+D10 -> 1041837 | H9: =E9+E10 -> 156250 | I9: =G9-H9 -> 885587
C10: Tarde | D10: 524400 | E10: =35150 -> 35150 | F10: =D10-E10 -> 489250
A11: Sabado | B11: 45724 | C11: Mañana | D11: 242353 | E11: =127000+20000 -> 147000 | F11: =D11-E11 -> 95353 | G11: =D11+D12 -> 541076 | H11: =E11+E12 -> 253000 | I11: =G11-H11 -> 288076
C12: Tarde | D12: 298723 | E12: =46000+60000 -> 106000 | F12: =D12-E12 -> 192723
A13: Lunes | B13: 45726 | C13: Mañana | D13: 373683 | E13: =36000+224017+13300+26600+126190+90300+80106+120000+1000 -> 717513 | F13: =D13-E13 -> -343830 | G13: =D13+D14 -> 767662 | H13: =E13+E14 -> 1278513 | I13: =G13-H13 -> -510851 | J13: alquiler
C14: Tarde | D14: 393979 | E14: =530000+4600+26400 -> 561000 | F14: =D14-E14 -> -167021
A15: Martes | B15: 45727 | C15: Mañana | D15: 318132 | E15: =257038+19100+13900+22200+18000+24013 -> 354251 | F15: =D15-E15 -> -36119 | G15: =D15+D16 -> 690654 | H15: =E15+E16 -> 413528 | I15: =G15-H15 -> 277126
C16: Tarde | D16: 372522 | E16: =8000+400+30000+20877 -> 59277 | F16: =D16-E16 -> 313245
A17: Miércoles | B17: 45728 | C17: Mañana | D17: 541840 | E17: =43960+155547+16000+10000+2000 -> 227507 | F17: =D17-E17 -> 314333 | G17: =D17+D18 -> 1096533 | H17: =E17+E18 -> 381307 | I17: =G17-H17 -> 715226
C18: Tarde | D18: 554693 | E18: =50000+30000+43800+30000 -> 153800 | F18: =D18-E18 -> 400893
A19: Jueves | B19: 45729 | C19: Mañana | D19: 522866 | E19: =15900+22215+306483+186178+51160+38000 -> 619936 | F19: =D19-E19 -> -97070 | G19: =D19+D20 -> 980766 | H19: =E19+E20 -> 1063802 | I19: =G19-H19 -> -83036
C20: Tarde | D20: 457900 | E20: =8000+16000+149000+28334+48000+8532+161000+25000 -> 443866 | F20: =D20-E20 -> 14034
A21: Viernes | B21: 45730 | C21: Mañana | D21: 483016 | E21: =105000+46050+17400+15000+9000+63379 -> 255829 | F21: =D21-E21 -> 227187 | G21: =D21+D22 -> 1027761 | H21: =E21+E22 -> 448392 | I21: =G21-H21 -> 579369
C22: Tarde | D22: 544745 | E22: =192563 -> 192563 | F22: =D22-E22 -> 352182
A23: Sabado | B23: 45731 | C23: Mañana | D23: 303857 | E23: 379090 | F23: =D23-E23 -> -75233 | G23: =D23+D24 -> 548993 | H23: =E23+E24 -> 415190 | I23: =G23-H23 -> 133803
C24: tarde | D24: 245136 | E24: 36100 | F24: =D24-E24 -> 209036
A25: Lunes | B25: 45733 | C25: Mañana | D25: 370612 | E25: =48450+13300+34210+65307 -> 161267 | F25: =D25-E25 -> 209345 | G25: =D25+D26 -> 745227 | H25: =E25+E26 -> 301620 | I25: =G25-H25 -> 443607
C26: Tarde | D26: 374615 | E26: =140353 -> 140353 | F26: =D26-E26 -> 234262
A27: Martes | B27: 45734 | C27: Mañana | D27: 334733 | E27: =36557+207862 -> 244419 | F27: =D27-E27 -> 90314 | G27: =D27+D28 -> 717331 | H27: =E27+E28 -> 421357 | I27: =G27-H27 -> 295974
C28: Tarde | D28: 382598 | E28: =126188+12350+26400+12000 -> 176938 | F28: =D28-E28 -> 205660
A29: Miércoles | B29: 45735 | C29: Mañana | D29: 452660 | E29: =131708+105000 -> 236708 | F29: =D29-E29 -> 215952 | G29: =D29+D30 -> 946439 | H29: =E29+E30 -> 443278 | I29: =G29-H29 -> 503161
C30: Tarde | D30: 493779 | E30: =18000+8000+180570 -> 206570 | F30: =D30-E30 -> 287209
A31: Jueves | B31: 45736 | C31: Mañana | D31: 597470 | E31: =44965+63650+16000+8000+8000 -> 140615 | F31: =D31-E31 -> 456855 | G31: =D31+D32 -> 1076961 | H31: =E31+E32 -> 304901 | I31: =G31-H31 -> 772060
C32: Tarde | D32: 479491 | E32: =164286 -> 164286 | F32: =D32-E32 -> 315205
A33: Viernes | B33: 45737 | C33: Mañana | D33: 445170 | E33: =40000+38000+12342+295726 -> 386068 | F33: =D33-E33 -> 59102 | G33: =D33+D34 -> 960317 | H33: =E33+E34 -> 667184 | I33: =G33-H33 -> 293133
C34: Tarde | D34: 515147 | E34: =76066+120200+22800+10650+26400+9000+6000+10000 -> 281116 | F34: =D34-E34 -> 234031
A35: Sabado | B35: 45738 | C35: Mañana | D35: 201635 | E35: =40000+15000 -> 55000 | F35: =D35-E35 -> 146635 | G35: =D35+D36 -> 413845 | H35: =E35+E36 -> 100250 | I35: =G35-H35 -> 313595
C36: tarde | D36: 212210 | E36: =12000+33250 -> 45250 | F36: =D36-E36 -> 166960 | T36: sabado normal
A37: Martes | B37: 45802 | C37: Mañana | D37: 448393 | E37: =63650+14850+72080+105000+22215+163608 -> 441403 | F37: =D37-E37 -> 6990 | G37: =D37+D38 -> 1056393 | H37: =E37+E38 -> 848090 | I37: =G37-H37 -> 208303
C38: Tarde | D38: 608000 | E38: =326687+60000+10000+10000 -> 406687 | F38: =D38-E38 -> 201313
A39: Miércoles | B39: 45803 | C39: Mañana | D39: 459531 | E39: =22215+33467+58900+5100+126200+36000 -> 281882 | F39: =D39-E39 -> 177649 | G39: =D39+D40 -> 1043949 | H39: =E39+E40 -> 565088 | I39: =G39-H39 -> 478861
C40: Tarde | D40: 584418 | E40: =233206+30000+20000 -> 283206 | F40: =D40-E40 -> 301212
...

Sheet Abril
A1: Día | B1: fecha | C1: Turno | D1: Diaria | G1: Total
D2: Ingreso Diario | E2: Gasto Diario | F2: Ganancia Diaria | G2: Ingreso | H2: Gasto | I2: Ganancia
A3: Martes | B3: 45748 | C3: Mañana | D3: 602829 | E3: =45600+16000+13300+53810+117000+26400+36000 -> 308110 | F3: =D3-E3 -> 294719 | G3: =D3+D4 -> 1224829 | H3: =E3+E4 -> 673227 | I3: =G3-H3 -> 551602
C4: Tarde | D4: 622000 | E4: =365117 -> 365117 | F4: =D4-E4 -> 256883
A5: Miércoles | B5: 45749 | C5: Mañana | D5: 195882 | E5: =45600+8000+114352+306496 -> 474448 | F5: =D5-E5 -> -278566 | G5: =D5+D6 -> 195882 | H5: =E5+E6 -> 474448 | I5: =G5-H5 -> -278566 | J5: Feriado
C6: Tarde | F6: =D6-E6 -> 0
A7: Jueves | B7: 45750 | C7: Mañana | D7: 479194 | E7: =8000+182178+33250+16000+26400+10000 -> 275828 | F7: =D7-E7 -> 203366 | G7: =D7+D8 -> 1022949 | H7: =E7+E8 -> 550898 | I7: =G7-H7 -> 472051
C8: Tarde | D8: 543755 | E8: =52870+126200+28000+68000 -> 275070 | F8: =D8-E8 -> 268685
A9: Viernes | B9: 45751 | C9: Mañana | D9: 687395 | E9: =56375+8000+17400+117000+36250 -> 235025 | F9: =D9-E9 -> 452370 | G9: =D9+D10 -> 1288990 | H9: =E9+E10 -> 621858 | I9: =G9-H9 -> 667132
C10: Tarde | D10: 601595 | E10: =386833 -> 386833 | F10: =D10-E10 -> 214762
A11: Sabado | B11: 45752 | C11: Mañana | D11: 278441 | E11: =4000+40000 -> 44000 | F11: =D11-E11 -> 234441 | G11: =D11+D12 -> 644321 | H11: =E11+E12 -> 88000 | I11: =G11-H11 -> 556321
C12: Tarde | D12: 365880 | E12: =36000+8000 -> 44000 | F12: =D12-E12 -> 321880
A13: Lunes | B13: 45754 | C13: Mañana | D13: 482128 | E13: =17400+127000+56375+33250+8000 -> 242025 | F13: =D13-E13 -> 240103 | G13: =D13+D14 -> 1051053 | H13: =E13+E14 -> 475098 | I13: =G13-H13 -> 575955
C14: Tarde | D14: 568925 | E14: =233073 -> 233073 | F14: =D14-E14 -> 335852
A15: Martes | B15: 45755 | C15: Mañana | D15: 450898 | E15: =341192 -> 341192 | F15: =D15-E15 -> 109706 | G15: =D15+D16 -> 1046010 | H15: =E15+E16 -> 704948 | I15: =G15-H15 -> 341062
C16: Tarde | D16: 595112 | E16: =8000+56050+26400+43306+75000+25000+130000 -> 363756 | F16: =D16-E16 -> 231356
A17: Miércoles | B17: 45756 | C17: Mañana | D17: 445865 | E17: =8000+33250+115500+32000+27000+74425+71841+16200+12300+15900+44000+10000 -> 460416 | F17: =D17-E17 -> -14551 | G17: =D17+D18 -> 1067691 | H17: =E17+E18 -> 990416 | I17: =G17-H17 -> 77275 | J17: alquiler
C18: Tarde | D18: 621826 | E18: =530000 -> 530000 | F18: =D18-E18 -> 91826
A19: Jueves | B19: 45757 | C19: Mañana | D19: 419087 | E19: =17400+8000+26400+33250+44000+10000 -> 139050 | F19: =D19-E19 -> 280037 | G19: =D19+D20 -> 867588 | H19: =E19+E20 -> 333850 | I19: =G19-H19 -> 533738 | J19: Paro univ.
C20: Tarde | D20: 448501 | E20: =130000+64800 -> 194800 | F20: =D20-E20 -> 253701
A21: Viernes | B21: 45758 | C21: Mañana | D21: 536048 | E21: =8000+63650+10500+58479+127000+35000+42000 -> 344629 | F21: =D21-E21 -> 191419 | G21: =D21+D22 -> 1147901 | H21: =E21+E22 -> 687466 | I21: =G21-H21 -> 460435
C22: Tarde | D22: 611853 | E22: =342837 -> 342837 | F22: =D22-E22 -> 269016
A23: Sabado | B23: 45759 | C23: Mañana | D23: 337648 | E23: =4000+13300+33250 -> 50550 | F23: =D23-E23 -> 287098 | G23: =D23+D24 -> 715397 | H23: =E23+E24 -> 425355 | I23: =G23-H23 -> 290042
C24: tarde | D24: 377749 | E24: 374805 | F24: =D24-E24 -> 2944
A25: Lunes | B25: 45761 | C25: Mañana | D25: 456653 | E25: =8000+17400+16000+33250+128700+56676+269666 -> 529692 | F25: =D25-E25 -> -73039 | G25: =D25+D26 -> 1088458 | H25: =E25+E26 -> 844927 | I25: =G25-H25 -> 243531
C26: Tarde | D26: 631805 | E26: =203830+111405 -> 315235 | F26: =D26-E26 -> 316570
A27: Martes | B27: 45762 | C27: Mañana | D27: 521316 | E27: =8000+12750+63650+373466 -> 457866 | F27: =D27-E27 -> 63450 | G27: =D27+D28 -> 1130568 | H27: =E27+E28 -> 669331 | I27: =G27-H27 -> 461237
C28: Tarde | D28: 609252 | E28: =43000+56675+68590+26400+6000+10800 -> 211465 | F28: =D28-E28 -> 397787
A29: Miércoles | B29: 45763 | C29: Mañana | D29: 548931 | E29: =16000+8540+128700+144865 -> 298105 | F29: =D29-E29 -> 250826 | G29: =D29+D30 -> 1270109 | H29: =E29+E30 -> 602040 | I29: =G29-H29 -> 668069
C30: Tarde | D30: 721178 | E30: =16000+127000+56675+33250+71010 -> 303935 | F30: =D30-E30 -> 417243
A31: Jueves | B31: 45764 | C31: Mañana | D31: 299163 | E31: =47625+426500 -> 474125 | F31: =D31-E31 -> -174962 | G31: =D31+D32 -> 751205 | H31: =E31+E32 -> 776925 | I31: =G31-H31 -> -25720
C32: Tarde | D32: 452042 | E32: =12200+60000+102000+39600+12000+20000+15000+42000 -> 302800 | F32: =D32-E32 -> 149242
A33: Viernes | B33: 45765 | C33: Mañana | F33: =D33-E33 -> 0 | G33: =D33+D34 -> 0 | H33: =E33+E34 -> 0 | I33: =G33-H33 -> 0 | J33: feriado viernes santo
C34: Tarde | F34: =D34-E34 -> 0
A35: Sabado | B35: 45766 | C35: Mañana | D35: 308210 | E35: =35937+8000+127000 -> 170937 | F35: =D35-E35 -> 137273 | G35: =D35+D36 -> 648499 | H35: =E35+E36 -> 240937 | I35: =G35-H35 -> 407562 | T35: Pago Sueldos
C36: tarde | D36: 340289 | E36: =20000+50000 -> 70000 | F36: =D36-E36 -> 270289 | T36: sabado normal
A37: Lunes | B37: 45768 | C37: Mañana | D37: 360373 | E37: =8000+32200+113945+14100+33250+40000 -> 241495 | F37: =D37-E37 -> 118878 | G37: =D37+D38 -> 906495 | H37: =E37+E38 -> 650981 | I37: =G37-H37 -> 255514
C38: Tarde | D38: 546122 | E38: =409486 -> 409486 | F38: =D38-E38 -> 136636
A39: Martes | B39: 45769 | C39: Mañana | D39: 377919 | E39: =8000+18000+33250+413000+34000+29000+21000 -> 556250 | F39: =D39-E39 -> -178331 | G39: =D39+D40 -> 854253 | H39: =E39+E40 -> 1297587 | I39: =G39-H39 -> -443334
C40: Tarde | D40: 476334 | E40: =450000+3400+65800+65800+56977+99360 -> 741337 | F40: =D40-E40 -> -265003
...

Sheet Mayo
A1: Día | B1: fecha | C1: Turno | D1: Diaria | G1: Total
D2: Ingreso Diario | E2: Gasto Diario | F2: Ganancia Diaria | G2: Ingreso | H2: Gasto | I2: Ganancia
A3: Jueves | B3: 45778 | C3: Mañana | F3: =D3-E3 -> 0 | G3: =D3+D4 -> 0 | H3: =E3+E4 -> 0 | I3: =G3-H3 -> 0 | J3: Feriado
C4: Tarde | F4: =D4-E4 -> 0
A5: Viernes | B5: 45779 | C5: Mañana | D5: 321782 | E5: =32200+38500+126200 -> 196900 | F5: =D5-E5 -> 124882 | G5: =D5+D6 -> 646328 | H5: =E5+E6 -> 278300 | I5: =G5-H5 -> 368028
C6: Tarde | D6: 324546 | E6: =10000+45000+18000+8400 -> 81400 | F6: =D6-E6 -> 243146
A7: Sabado | B7: 45780 | C7: Mañana | D7: 242900 | E7: =89263 -> 89263 | F7: =D7-E7 -> 153637 | G7: =D7+D8 -> 560000 | H7: =E7+E8 -> 89263 | I7: =G7-H7 -> 470737
C8: Tarde | D8: 317100 | E8: 0 | F8: =D8-E8 -> 317100
A9: Lunes | B9: 45782 | C9: Mañana | D9: 457178 | E9: =10000+8000+13750+74500+126300+39600+126200 -> 398350 | F9: =D9-E9 -> 58828 | G9: =D9+D10 -> 1164754 | H9: =E9+E10 -> 724642 | I9: =G9-H9 -> 440112
C10: Tarde | D10: 707576 | E10: =326292 -> 326292 | F10: =D10-E10 -> 381284
A11: Martes | B11: 45783 | C11: Mañana | D11: 373594 | E11: =8000+49912+60711+7200+32500 -> 158323 | F11: =D11-E11 -> 215271 | G11: =D11+D12 -> 945840 | H11: =E11+E12 -> 443223 | I11: =G11-H11 -> 502617
C12: Tarde | D12: 572246 | E12: =272295+12605 -> 284900 | F12: =D12-E12 -> 287346
A13: Miércoles | B13: 45784 | C13: Mañana | D13: 417000 | E13: =8000+30000+14200+59263 -> 111463 | F13: =D13-E13 -> 305537 | G13: =D13+D14 -> 969232 | H13: =E13+E14 -> 381531 | I13: =G13-H13 -> 587701
C14: Tarde | D14: 552232 | E14: =270068 -> 270068 | F14: =D14-E14 -> 282164
A15: Jueves | B15: 45785 | C15: Mañana | D15: 561043 | E15: =274961 -> 274961 | F15: =D15-E15 -> 286082 | G15: =D15+D16 -> 1242905 | H15: =E15+E16 -> 548174 | I15: =G15-H15 -> 694731
C16: Tarde | D16: 681862 | E16: =59263+8000+34450+26500+130000+15000 -> 273213 | F16: =D16-E16 -> 408649
A17: Viernes | B17: 45786 | C17: Mañana | D17: 535369 | E17: =21200+56100+165000+8000+26500+342644 -> 619444 | F17: =D17-E17 -> -84075 | G17: =D17+D18 -> 1124652 | H17: =E17+E18 -> 1194444 | I17: =G17-H17 -> -69792 | J17: alquiler
C18: Tarde | D18: 589283 | E18: =530000+23000+15000+7000 -> 575000 | F18: =D18-E18 -> 14283
A19: Sabado | B19: 45787 | C19: Mañana | D19: 241794 | E19: =354980 -> 354980 | F19: =D19-E19 -> -113186 | G19: =D19+D20 -> 606247 | H19: =E19+E20 -> 487930 | I19: =G19-H19 -> 118317
C20: tarde | D20: 364453 | E20: =12750+8000+22200+27000+63000 -> 132950 | F20: =D20-E20 -> 231503
A21: Lunes | B21: 45789 | C21: Mañana | D21: 433784 | E21: =55000+135000+26561+18450+78863 -> 313874 | F21: =D21-E21 -> 119910 | G21: =D21+D22 -> 975335 | H21: =E21+E22 -> 546239 | I21: =G21-H21 -> 429096
C22: Tarde | D22: 541551 | E22: =224365+8000 -> 232365 | F22: =D22-E22 -> 309186
A23: Martes | B23: 45790 | C23: Mañana | D23: 436559 | E23: =8000+82000+22200+66832+50000+50000 -> 279032 | F23: =D23-E23 -> 157527 | G23: =D23+D24 -> 981097 | H23: =E23+E24 -> 618462 | I23: =G23-H23 -> 362635
C24: Tarde | D24: 544538 | E24: =339430 -> 339430 | F24: =D24-E24 -> 205108
A25: Miércoles | B25: 45791 | C25: Mañana | D25: 593516 | E25: =40000+8000+35400+15650+104000 -> 203050 | F25: =D25-E25 -> 390466 | G25: =D25+D26 -> 1102682 | H25: =E25+E26 -> 446316 | I25: =G25-H25 -> 656366
C26: Tarde | D26: 509166 | E26: =49912+177354+16000 -> 243266 | F26: =D26-E26 -> 265900
A27: Jueves | B27: 45792 | C27: Mañana | D27: 529318 | E27: =8000+165000+61420+11200+135843 -> 381463 | F27: =D27-E27 -> 147855 | G27: =D27+D28 -> 1152379 | H27: =E27+E28 -> 683162 | I27: =G27-H27 -> 469217
C28: Tarde | D28: 623061 | E28: =231699+70000 -> 301699 | F28: =D28-E28 -> 321362
A29: Viernes | B29: 45793 | C29: Mañana | D29: 625516 | E29: =8000+511045 -> 519045 | F29: =D29-E29 -> 106471 | G29: =D29+D30 -> 1187737 | H29: =E29+E30 -> 788182 | I29: =G29-H29 -> 399555
C30: Tarde | D30: 562221 | E30: =97487+46000+18450+32200+25000+50000 -> 269137 | F30: =D30-E30 -> 293084
A31: Sabado | B31: 45794 | C31: Mañana | D31: 337677 | E31: =8000+67000+136000+32266+2889+136800 -> 382955 | F31: =D31-E31 -> -45278 | G31: =D31+D32 -> 590491 | H31: =E31+E32 -> 455526 | I31: =G31-H31 -> 134965 | T31: Pago Sueldos
C32: tarde | D32: 252814 | E32: =57571+15000 -> 72571 | F32: =D32-E32 -> 180243 | T32: sabado normal
A33: Lunes | B33: 45796 | C33: Mañana | D33: 376344 | E33: =8000+79932+20000+286687 -> 394619 | F33: =D33-E33 -> -18275 | G33: =D33+D34 -> 950368 | H33: =E33+E34 -> 824613 | I33: =G33-H33 -> 125755
C34: Tarde | D34: 574024 | E34: =429994 -> 429994 | F34: =D34-E34 -> 144030
A35: Martes | B35: 45797 | C35: Mañana | D35: 375808 | E35: =4000+39600+21040+32200+32100 -> 128940 | F35: =D35-E35 -> 246868 | G35: =D35+D36 -> 815865 | H35: =E35+E36 -> 407665 | I35: =G35-H35 -> 408200
C36: Tarde | D36: 440057 | E36: =278725 -> 278725 | F36: =D36-E36 -> 161332
A37: Miércoles | B37: 45798 | C37: Mañana | D37: 490208 | E37: =8000+136000+18450 -> 162450 | F37: =D37-E37 -> 327758 | G37: =D37+D38 -> 1155294 | H37: =E37+E38 -> 325872 | I37: =G37-H37 -> 829422
C38: Tarde | D38: 665086 | E38: =38500+124922 -> 163422 | F38: =D38-E38 -> 501664
A39: Jueves | B39: 45799 | C39: Mañana | D39: 484751 | E39: =8000+79932+61000+53355+106570 -> 308857 | F39: =D39-E39 -> 175894 | G39: =D39+D40 -> 1043580 | H39: =E39+E40 -> 641516 | I39: =G39-H39 -> 402064
C40: Tarde | D40: 558829 | E40: =302659+20000+10000 -> 332659 | F40: =D40-E40 -> 226170
...

Sheet Junio
A1: Día | B1: fecha | C1: Turno | D1: Diaria | G1: Total
D2: Ingreso Diario | E2: Gasto Diario | F2: Ganancia Diaria | G2: Ingreso | H2: Gasto | I2: Ganancia
A3: Lunes | B3: 45779 | C3: Mañana | D3: 446235 | E3: =8000+59263+34400 -> 101663 | F3: =D3-E3 -> 344572 | G3: =D3+D4 -> 932504 | H3: =E3+E4 -> 350306 | I3: =G3-H3 -> 582198
C4: Tarde | D4: 486269 | E4: 248643 | F4: =D4-E4 -> 237626
A5: Martes | B5: 45780 | C5: Mañana | D5: 379385 | E5: =8000+80500+21039+165000+13650+136000 -> 424189 | F5: =D5-E5 -> -44804 | G5: =D5+D6 -> 974257 | H5: =E5+E6 -> 741638 | I5: =G5-H5 -> 232619
C6: Tarde | D6: 594872 | E6: =317449 -> 317449 | F6: =D6-E6 -> 277423
A7: Miércoles | B7: 45781 | C7: Mañana | D7: 499779 | E7: =8000+227877 -> 235877 | F7: =D7-E7 -> 263902 | G7: =D7+D8 -> 1063744 | H7: =E7+E8 -> 378785 | I7: =G7-H7 -> 684959
C8: Tarde | D8: 563965 | E8: =98188+39600+5120 -> 142908 | F8: =D8-E8 -> 421057
A9: Jueves | B9: 45782 | C9: Mañana | D9: 418962 | E9: =8000+45400+85090+131000+20800+52673+97487+3000+3000 -> 446450 | F9: =D9-E9 -> -27488 | G9: =D9+D10 -> 927066 | H9: =E9+E10 -> 970087 | I9: =G9-H9 -> -43021
C10: Tarde | D10: 508104 | E10: =523637 -> 523637 | F10: =D10-E10 -> -15533
A11: Viernes | B11: 45783 | C11: Mañana | D11: 600666 | E11: =8000+132500 -> 140500 | F11: =D11-E11 -> 460166 | G11: =D11+D12 -> 1093745 | H11: =E11+E12 -> 476775 | I11: =G11-H11 -> 616970 | J11: alquiler
C12: Tarde | D12: 493079 | E12: =131000+205275 -> 336275 | F12: =D12-E12 -> 156804
A13: Sabado | B13: 45784 | C13: Mañana | D13: 444676 | E13: =8000+25000+15000+10000 -> 58000 | F13: =D13-E13 -> 386676 | G13: =D13+D14 -> 904375 | H13: =E13+E14 -> 860318 | I13: =G13-H13 -> 44057
C14: tarde | D14: 459699 | E14: =802318 -> 802318 | F14: =D14-E14 -> -342619
A15: Lunes | B15: 45786 | C15: Mañana | D15: 380193 | E15: =8000+100782+23400+165000+12900+39600 -> 349682 | F15: =D15-E15 -> 30511 | G15: =D15+D16 -> 938813 | H15: =E15+E16 -> 764527 | I15: =G15-H15 -> 174286
C16: Tarde | D16: 558620 | E16: =414845 -> 414845 | F16: =D16-E16 -> 143775
A17: Martes | B17: 45787 | C17: Mañana | D17: 431110 | E17: =8000+74500+11688+15000 -> 109188 | F17: =D17-E17 -> 321922 | G17: =D17+D18 -> 1092696 | H17: =E17+E18 -> 887564 | I17: =G17-H17 -> 205132
C18: Tarde | D18: 661586 | E18: =248376+530000 -> 778376 | F18: =D18-E18 -> -116790
A19: Miércoles | B19: 45788 | C19: Mañana | D19: 431826 | E19: =8000+22000+83401+26500 -> 139901 | F19: =D19-E19 -> 291925 | G19: =D19+D20 -> 942436 | H19: =E19+E20 -> 265071 | I19: =G19-H19 -> 677365
C20: Tarde | D20: 510610 | E20: =125170 -> 125170 | F20: =D20-E20 -> 385440
A21: Jueves | B21: 45789 | C21: Mañana | D21: 585508 | E21: =8000+26500+76420+92200+130100+80000 -> 413220 | F21: =D21-E21 -> 172288 | G21: =D21+D22 -> 1082958 | H21: =E21+E22 -> 660882 | I21: =G21-H21 -> 422076
C22: Tarde | D22: 497450 | E22: =207662+40000 -> 247662 | F22: =D22-E22 -> 249788
A23: Viernes | B23: 45790 | C23: Mañana | D23: 522449 | E23: =8000+46000+18200+90969 -> 163169 | F23: =D23-E23 -> 359280 | G23: =D23+D24 -> 1146992 | H23: =E23+E24 -> 705175 | I23: =G23-H23 -> 441817
C24: Tarde | D24: 624543 | E24: =542006 -> 542006 | F24: =D24-E24 -> 82537
A25: Sabado | B25: 45791 | C25: Mañana | D25: 355083 | E25: 8000 | F25: =D25-E25 -> 347083 | G25: =D25+D26 -> 563706 | H25: =E25+E26 -> 55500 | I25: =G25-H25 -> 508206
C26: tarde | D26: 208623 | E26: 47500 | F26: =D26-E26 -> 161123
A27: Lunes | B27: 45793 | C27: Mañana | D27: 169243 | E27: =22000+24000 -> 46000 | F27: =D27-E27 -> 123243 | G27: =D27+D28 -> 530893 | H27: =E27+E28 -> 57000 | I27: =G27-H27 -> 473893 | J27: Feriado | T27: Pago Sueldos
C28: Tarde | D28: 361650 | E28: =7000+4000 -> 11000 | F28: =D28-E28 -> 350650 | T28: sabado normal
A29: Martes | B29: 45794 | C29: Mañana | D29: 423217 | E29: =8000+131000+22000+38500+39600+165000 -> 404100 | F29: =D29-E29 -> 19117 | G29: =D29+D30 -> 973271 | H29: =E29+E30 -> 885809 | I29: =G29-H29 -> 87462
C30: Tarde | D30: 550054 | E30: =228842+45000+20000+16000+2846+32221+136800 -> 481709 | F30: =D30-E30 -> 68345
A31: Miércoles | B31: 45795 | C31: Mañana | D31: 534766 | E31: =8000+16000+232734+50929+57500+23000 -> 388163 | F31: =D31-E31 -> 146603 | G31: =D31+D32 -> 1021036 | H31: =E31+E32 -> 945948 | I31: =G31-H31 -> 75088
C32: Tarde | D32: 486270 | E32: =15000+83522+100000+59263+300000 -> 557785 | F32: =D32-E32 -> -71515
A33: Jueves | B33: 45796 | C33: Mañana | D33: 436107 | E33: =8000+22000+58760+84570+444237 -> 617567 | F33: =D33-E33 -> -181460 | G33: =D33+D34 -> 1022448 | H33: =E33+E34 -> 1017567 | I33: =G33-H33 -> 4881
C34: Tarde | D34: 586341 | E34: 400000 | F34: =D34-E34 -> 186341
A35: Viernes | B35: 45797 | C35: Mañana | D35: 299510 | E35: =8000+70000+10000+45000+46000 -> 179000 | F35: =D35-E35 -> 120510 | G35: =D35+D36 -> 689200 | H35: =E35+E36 -> 470800 | I35: =G35-H35 -> 218400 | J35: Feriado
C36: Tarde | D36: 389690 | E36: 291800 | F36: =D36-E36 -> 97890
A37: Sabado | B37: 45798 | C37: Mañana | D37: 211961 | E37: =8000+88000 -> 96000 | F37: =D37-E37 -> 115961 | G37: =D37+D38 -> 597141 | H37: =E37+E38 -> 631605 | I37: =G37-H37 -> -34464
C38: Tarde | D38: 385180 | E38: =535605 -> 535605 | F38: =D38-E38 -> -150425
A39: Lunes | B39: 45800 | C39: Mañana | D39: 293564 | E39: =8000+11000+441168 -> 460168 | F39: =D39-E39 -> -166604 | G39: =D39+D40 -> 709134 | H39: =E39+E40 -> 560861 | I39: =G39-H39 -> 148273
C40: Tarde | D40: 415570 | E40: =1600+61093+38000 -> 100693 | F40: =D40-E40 -> 314877
...

Sheet Julio
A1: Día | B1: fecha | C1: Turno | D1: Diaria | G1: Total
D2: Ingreso Diario | E2: Gasto Diario | F2: Ganancia Diaria | G2: Ingreso | H2: Gasto | I2: Ganancia
A3: Martes | B3: 45839 | C3: Mañana | D3: 362860 | E3: =8000+18900+34400+31000+59263+131000 -> 282563 | F3: =D3-E3 -> 80297 | G3: =D3+D4 -> 852798 | H3: =E3+E4 -> 566665 | I3: =G3-H3 -> 286133
C4: Tarde | D4: 489938 | E4: =214102+50000+10000+10000 -> 284102 | F4: =D4-E4 -> 205836
A5: Miércoles | B5: 45840 | C5: Mañana | D5: 502242 | E5: =165000 -> 165000 | F5: =D5-E5 -> 337242 | G5: =D5+D6 -> 1088978 | H5: =E5+E6 -> 275098 | I5: =G5-H5 -> 813880
C6: Tarde | D6: 586736 | E6: =8000+32598+50000+19500 -> 110098 | F6: =D6-E6 -> 476638
A7: Jueves | B7: 45841 | C7: Mañana | D7: 349799 | E7: =560520 -> 560520 | F7: =D7-E7 -> -210721 | G7: =D7+D8 -> 892098 | H7: =E7+E8 -> 733801 | I7: =G7-H7 -> 158297
C8: Tarde | D8: 542299 | E8: =8000+83401+59880+22000 -> 173281 | F8: =D8-E8 -> 369018
A9: Viernes | B9: 45842 | C9: Mañana | D9: 510921 | E9: =8000+22000+115000 -> 145000 | F9: =D9-E9 -> 365921 | G9: =D9+D10 -> 979791 | H9: =E9+E10 -> 275020 | I9: =G9-H9 -> 704771
C10: Tarde | D10: 468870 | E10: =130020 -> 130020 | F10: =D10-E10 -> 338850
A11: Sabado | B11: 45843 | C11: Mañana | D11: 235692 | E11: =8000+19000+35000 -> 62000 | F11: =D11-E11 -> 173692 | G11: =D11+D12 -> 479117 | H11: =E11+E12 -> 643172 | I11: =G11-H11 -> -164055
C12: tarde | D12: 243425 | E12: =581172 -> 581172 | F12: =D12-E12 -> -337747
A13: Lunes | B13: 45845 | C13: Mañana | D13: 310044 | E13: =200870+71500+45500 -> 317870 | F13: =D13-E13 -> -7826 | G13: =D13+D14 -> 733030 | H13: =E13+E14 -> 491920 | I13: =G13-H13 -> 241110
C14: Tarde | D14: 422986 | E14: =74050+100000 -> 174050 | F14: =D14-E14 -> 248936
A15: Martes | B15: 45846 | C15: Mañana | D15: 397752 | E15: =165000+214960+65855+57500 -> 503315 | F15: =D15-E15 -> -105563 | G15: =D15+D16 -> 905211 | H15: =E15+E16 -> 1033315 | I15: =G15-H15 -> -128104 | J15: alquiler
C16: Tarde | D16: 507459 | E16: =530000 -> 530000 | F16: =D16-E16 -> -22541
A17: Miércoles | B17: 45847 | C17: Mañana | D17: 281207 | E17: =37000+9000+110000 -> 156000 | F17: =D17-E17 -> 125207 | G17: =D17+D18 -> 694410 | H17: =E17+E18 -> 306000 | I17: =G17-H17 -> 388410 | J17: Feriado
C18: Tarde | D18: 413203 | E18: =70000+80000 -> 150000 | F18: =D18-E18 -> 263203
A19: Jueves | B19: 45848 | C19: Mañana | D19: 255973 | E19: =9000+229425 -> 238425 | F19: =D19-E19 -> 17548 | G19: =D19+D20 -> 615657 | H19: =E19+E20 -> 292225 | I19: =G19-H19 -> 323432
C20: Tarde | D20: 359684 | E20: =22200+23400+8200 -> 53800 | F20: =D20-E20 -> 305884
A21: Viernes | B21: 45849 | C21: Mañana | D21: 243851 | E21: =9000+115000+67430+40000 -> 231430 | F21: =D21-E21 -> 12421 | G21: =D21+D22 -> 749520 | H21: =E21+E22 -> 525736 | I21: =G21-H21 -> 223784
C22: Tarde | D22: 505669 | E22: =294306 -> 294306 | F22: =D22-E22 -> 211363
A23: Sabado | B23: 45850 | C23: Mañana | D23: 373814 | E23: =4500+20000 -> 24500 | F23: =D23-E23 -> 349314 | G23: =D23+D24 -> 713877 | H23: =E23+E24 -> 49500 | I23: =G23-H23 -> 664377
C24: tarde | D24: 340063 | E24: 25000 | F24: =D24-E24 -> 315063
A25: Lunes | B25: 45852 | C25: Mañana | D25: 296097 | E25: =9000+90969+15800+10000+20000+35000 -> 180769 | F25: =D25-E25 -> 115328 | G25: =D25+D26 -> 694427 | H25: =E25+E26 -> 702347 | I25: =G25-H25 -> -7920 | T25: Pago Sueldos
C26: Tarde | D26: 398330 | E26: =521578 -> 521578 | F26: =D26-E26 -> -123248 | T26: sabado normal
A27: Martes | B27: 45853 | C27: Mañana | D27: 226652 | E27: =9000+94000+60000 -> 163000 | F27: =D27-E27 -> 63652 | G27: =D27+D28 -> 600795 | H27: =E27+E28 -> 348000 | I27: =G27-H27 -> 252795
C28: Tarde | D28: 374143 | E28: =165000+20000 -> 185000 | F28: =D28-E28 -> 189143
A29: Miércoles | B29: 45854 | C29: Mañana | D29: 326046 | E29: =9000+133000+63183 -> 205183 | F29: =D29-E29 -> 120863 | G29: =D29+D30 -> 705752 | H29: =E29+E30 -> 474445 | I29: =G29-H29 -> 231307
C30: Tarde | D30: 379706 | E30: =269262 -> 269262 | F30: =D30-E30 -> 110444
A31: Jueves | B31: 45855 | C31: Mañana | D31: 296118 | E31: =9000+59786+26500+140000+59860 -> 295146 | F31: =D31-E31 -> 972 | G31: =D31+D32 -> 721269 | H31: =E31+E32 -> 753572 | I31: =G31-H31 -> -32303
C32: Tarde | D32: 425151 | E32: =458426 -> 458426 | F32: =D32-E32 -> -33275
A33: Viernes | B33: 45856 | C33: Mañana | D33: 251885 | E33: =9000+34400+10000 -> 53400 | F33: =D33-E33 -> 198485 | G33: =D33+D34 -> 688797 | H33: =E33+E34 -> 111200 | I33: =G33-H33 -> 577597
C34: Tarde | D34: 436912 | E34: =25000+32800 -> 57800 | F34: =D34-E34 -> 379112
A35: Sabado | B35: 45857 | C35: Mañana | D35: 237454 | E35: =4500 -> 4500 | F35: =D35-E35 -> 232954 | G35: =D35+D36 -> 548681 | H35: =E35+E36 -> 404514 | I35: =G35-H35 -> 144167
C36: Tarde | D36: 311227 | E36: =400014 -> 400014 | F36: =D36-E36 -> -88787
A37: Lunes | B37: 45859 | C37: Mañana | D37: 278864 | E37: =9000+16650+30000 -> 55650 | F37: =D37-E37 -> 223214 | G37: =D37+D38 -> 635661 | H37: =E37+E38 -> 195650 | I37: =G37-H37 -> 440011
C38: Tarde | D38: 356797 | E38: =80000+60000 -> 140000 | F38: =D38-E38 -> 216797
A39: Martes | B39: 45860 | C39: Mañana | D39: 376642 | E39: =9000+45400+150000+83401 -> 287801 | F39: =D39-E39 -> 88841 | G39: =D39+D40 -> 866042 | H39: =E39+E40 -> 534126 | I39: =G39-H39 -> 331916
C40: Tarde | D40: 489400 | E40: =215925+30400 -> 246325 | F40: =D40-E40 -> 243075
...

Sheet Agosto_25
A1: Día | B1: fecha | C1: Turno | D1: Diaria | G1: Total
D2: Ingreso Diario | E2: Gasto Diario | F2: Ganancia Diaria | G2: Ingreso | H2: Gasto | I2: Ganancia
A3: Viernes | B3: 45870 | C3: Mañana | D3: 483272 | E3: =4500+32500+13800+242518 -> 293318 | F3: =D3-E3 -> 189954 | G3: =D3+D4 -> 967905 | H3: =E3+E4 -> 574670 | I3: =G3-H3 -> 393235
C4: Tarde | D4: 484633 | E4: =139000+11000+70000+6352+40000+15000 -> 281352 | F4: =D4-E4 -> 203281
A5: Sabado | B5: 45871 | C5: Mañana | D5: 273041 | E5: =4500+66000 -> 70500 | F5: =D5-E5 -> 202541 | G5: =D5+D6 -> 541490 | H5: =E5+E6 -> 589675 | I5: =G5-H5 -> -48185
C6: tarde | D6: 268449 | E6: =519175 -> 519175 | F6: =D6-E6 -> -250726
A7: Lunes | B7: 45873 | C7: Mañana | D7: 378962 | E7: =9000+9800+80283+317899+38500 -> 455482 | F7: =D7-E7 -> -76520 | G7: =D7+D8 -> 960363 | H7: =E7+E8 -> 997482 | I7: =G7-H7 -> -37119
C8: Tarde | D8: 581401 | E8: =542000 -> 542000 | F8: =D8-E8 -> 39401
A9: Martes | B9: 45874 | C9: Mañana | D9: 482888 | E9: =9000+240529 -> 249529 | F9: =D9-E9 -> 233359 | G9: =D9+D10 -> 1171092 | H9: =E9+E10 -> 491652 | I9: =G9-H9 -> 679440
C10: Tarde | D10: 688204 | E10: =74500+60000+38223+34400+30000+5000 -> 242123 | F10: =D10-E10 -> 446081
A11: Miércoles | B11: 45875 | C11: Mañana | D11: 395833 | E11: =9000+260063 -> 269063 | F11: =D11-E11 -> 126770 | G11: =D11+D12 -> 886838 | H11: =E11+E12 -> 649002 | I11: =G11-H11 -> 237836
C12: Tarde | D12: 491005 | E12: =38500+139000+21039+9800+171600 -> 379939 | F12: =D12-E12 -> 111066
A13: Jueves | B13: 45876 | C13: Mañana | D13: 423552 | E13: =9000+69680+38500+60221+147841+80000 -> 405242 | F13: =D13-E13 -> 18310 | G13: =D13+D14 -> 912953 | H13: =E13+E14 -> 1035242 | I13: =G13-H13 -> -122289 | J13: alquiler
C14: Tarde | D14: 489401 | E14: =630000 -> 630000 | F14: =D14-E14 -> -140599
A15: Viernes | B15: 45877 | C15: Mañana | D15: 517849 | E15: =9000+38500+59263+17700+23400+70000+275000+107000+15000+20500+95450 -> 730813 | F15: =D15-E15 -> -212964 | G15: =D15+D16 -> 1238222 | H15: =E15+E16 -> 1147379 | I15: =G15-H15 -> 90843
C16: Tarde | D16: 720373 | E16: =416566 -> 416566 | F16: =D16-E16 -> 303807
A17: Sabado | B17: 45878 | C17: Mañana | D17: 255751 | E17: =9000+83500+70000 -> 162500 | F17: =D17-E17 -> 93251 | G17: =D17+D18 -> 621187 | H17: =E17+E18 -> 400500 | I17: =G17-H17 -> 220687
C18: tarde | D18: 365436 | E18: =70000+130000+20000+18000 -> 238000 | F18: =D18-E18 -> 127436
A19: Lunes | B19: 45880 | C19: Mañana | D19: 280698 | E19: =9000+34400+60000 -> 103400 | F19: =D19-E19 -> 177298 | G19: =D19+D20 -> 712317 | H19: =E19+E20 -> 308694 | I19: =G19-H19 -> 403623 | T19: Pago Sueldos
C20: Tarde | D20: 431619 | E20: =205294 -> 205294 | F20: =D20-E20 -> 226325 | T20: sabado normal
A21: Martes | B21: 45881 | C21: Mañana | D21: 325478 | E21: =9000+85181+25600+171600+38500 -> 329881 | F21: =D21-E21 -> -4403 | G21: =D21+D22 -> 864354 | H21: =E21+E22 -> 617472 | I21: =G21-H21 -> 246882
C22: Tarde | D22: 538876 | E22: =247591+30000+10000 -> 287591 | F22: =D22-E22 -> 251285
A23: Miércoles | B23: 45882 | C23: Mañana | D23: 386846 | E23: =9000+22600+48108+185150 -> 264858 | F23: =D23-E23 -> 121988 | G23: =D23+D24 -> 902660 | H23: =E23+E24 -> 622771 | I23: =G23-H23 -> 279889
C24: Tarde | D24: 515814 | E24: =357913 -> 357913 | F24: =D24-E24 -> 157901
A25: Jueves | B25: 45883 | C25: Mañana | D25: 398615 | E25: =9000+46000+44398+163490 -> 262888 | F25: =D25-E25 -> 135727 | G25: =D25+D26 -> 949403 | H25: =E25+E26 -> 380488 | I25: =G25-H25 -> 568915
C26: Tarde | D26: 550788 | E26: =52600+15000+15000+20000+15000 -> 117600 | F26: =D26-E26 -> 433188
A27: Viernes | B27: 45884 | C27: Mañana | D27: 269026 | E27: =9000+15900+67500 -> 92400 | F27: =D27-E27 -> 176626 | G27: =D27+D28 -> 820259 | H27: =E27+E28 -> 134650 | I27: =G27-H27 -> 685609
C28: Tarde | D28: 551233 | E28: =14700+27550 -> 42250 | F28: =D28-E28 -> 508983
A29: Sabado | B29: 45885 | C29: Mañana | D29: 151215 | E29: =9000 -> 9000 | F29: =D29-E29 -> 142215 | G29: =D29+D30 -> 486297 | H29: =E29+E30 -> 246356 | I29: =G29-H29 -> 239941
C30: Tarde | D30: 335082 | E30: =237356 -> 237356 | F30: =D30-E30 -> 97726
A31: Lunes | B31: 45887 | C31: Mañana | D31: 420389 | E31: =9000+26500+42434 -> 77934 | F31: =D31-E31 -> 342455 | G31: =D31+D32 -> 981026 | H31: =E31+E32 -> 150177 | I31: =G31-H31 -> 830849
C32: Tarde | D32: 560637 | E32: =60243+12000 -> 72243 | F32: =D32-E32 -> 488394
A33: Martes | B33: 45888 | C33: Mañana | D33: 418057 | E33: =9000+65500+10000+23000+82448+70000+5000+174600+11900+60000+15000+14000 -> 540448 | F33: =D33-E33 -> -122391 | G33: =D33+D34 -> 1128925 | H33: =E33+E34 -> 1109978 | I33: =G33-H33 -> 18947
C34: Tarde | D34: 710868 | E34: =569530 -> 569530 | F34: =D34-E34 -> 141338
A35: Miercoles | B35: 45889 | C35: Mañana | D35: 321144 | E35: =470000 -> 470000 | F35: =D35-E35 -> -148856 | G35: =D35+D36 -> 899002 | H35: =E35+E36 -> 864087 | I35: =G35-H35 -> 34915
C36: Tarde | D36: 577858 | E36: =9000+14500+224644+60243+17700+33000+35000 -> 394087 | F36: =D36-E36 -> 183771 | M36: Ingreso | N36: 1
A37: Jueves | B37: 45890 | C37: Mañana | D37: 300746 | E37: =9000+15750+20000+15000+86610 -> 146360 | F37: =D37-E37 -> 154386 | G37: =D37+D38 -> 852525 | H37: =E37+E38 -> 330216 | I37: =G37-H37 -> 522309 | M37: Gasto | N37: =H55*100/G55/100 -> 0.66829246
C38: Tarde | D38: 551779 | E38: =26500+157356 -> 183856 | F38: =D38-E38 -> 367923 | M38: Ganancia | N38: =(100%-N37) -> 0.33170754
A39: Viernes | B39: 45891 | C39: Mañana | D39: 419835 | E39: =9000+102000+174600+140000 -> 425600 | F39: =D39-E39 -> -5765 | G39: =D39+D40 -> 1049637 | H39: =E39+E40 -> 789799 | I39: =G39-H39 -> 259838
C40: Tarde | D40: 629802 | E40: =81752+20000+262447 -> 364199 | F40: =D40-E40 -> 265603
...

Sheet Septiembre_25
A1: Día | B1: fecha | C1: Turno | D1: Diaria | G1: Total
D2: Ingreso Diario | E2: Gasto Diario | F2: Ganancia Diaria | G2: Ingreso | H2: Gasto | I2: Ganancia
A3: Lunes | B3: 45901 | C3: Mañana | D3: 334993 | E3: =18000+135100+60243+60000 -> 273343 | F3: =D3-E3 -> 61650 | G3: =D3+D4 -> 1001766 | H3: =E3+E4 -> 646251 | I3: =G3-H3 -> 355515
C4: Tarde | D4: 666773 | E4: =277508+50000+45400 -> 372908 | F4: =D4-E4 -> 293865
A5: Martes | B5: 45902 | C5: Mañana | D5: 288847 | E5: =9000+195361+19400 -> 223761 | F5: =D5-E5 -> 65086 | G5: =D5+D6 -> 827559 | H5: =E5+E6 -> 535261 | I5: =G5-H5 -> 292298
C6: Tarde | D6: 538712 | E6: =140000+45000+40000+60000+26500 -> 311500 | F6: =D6-E6 -> 227212
A7: Miércoles | B7: 45903 | C7: Mañana | D7: 476105 | E7: =9000+16200+72051 -> 97251 | F7: =D7-E7 -> 378854 | G7: =D7+D8 -> 1007785 | H7: =E7+E8 -> 228916 | I7: =G7-H7 -> 778869
C8: Tarde | D8: 531680 | E8: =28500+88165+15000 -> 131665 | F8: =D8-E8 -> 400015
A9: Jueves | B9: 45904 | C9: Mañana | D9: 408104 | E9: =9000+510140 -> 519140 | F9: =D9-E9 -> -111036 | G9: =D9+D10 -> 1085132 | H9: =E9+E10 -> 673253 | I9: =G9-H9 -> 411879
C10: Tarde | D10: 677028 | E10: =60243+42370+51500 -> 154113 | F10: =D10-E10 -> 522915
A11: Viernes | B11: 45905 | C11: Mañana | D11: 486222 | E11: =9000+55000+14700+264900 -> 343600 | F11: =D11-E11 -> 142622 | G11: =D11+D12 -> 1041548 | H11: =E11+E12 -> 411205 | I11: =G11-H11 -> 630343
C12: Tarde | D12: 555326 | E12: =27605+10000+30000 -> 67605 | F12: =D12-E12 -> 487721
A13: Sabado | B13: 45906 | C13: Mañana | D13: 235071 | E13: =9000+35000+4026+18103+19500+137000+37124 -> 259753 | F13: =D13-E13 -> -24682 | G13: =D13+D14 -> 665708 | H13: =E13+E14 -> 394753 | I13: =G13-H13 -> 270955
C14: tarde | D14: 430637 | E14: 135000 | F14: =D14-E14 -> 295637
A15: Lunes | B15: 45908 | C15: Mañana | D15: 419379 | E15: =51400+80280+40000+20000 -> 191680 | F15: =D15-E15 -> 227699 | G15: =D15+D16 -> 1028148 | H15: =E15+E16 -> 529960 | I15: =G15-H15 -> 498188
C16: Tarde | D16: 608769 | E16: 338280 | F16: =D16-E16 -> 270489
A17: Martes | B17: 45909 | C17: Mañana | D17: 324998 | E17: =9000+17700+353524+18000+57244+15000+15400+60243 -> 546111 | F17: =D17-E17 -> -221113 | G17: =D17+D18 -> 862340 | H17: =E17+E18 -> 1176111 | I17: =G17-H17 -> -313771 | J17: alquiler
C18: Tarde | D18: 537342 | E18: 630000 | F18: =D18-E18 -> -92658
A19: Miércoles | B19: 45910 | C19: Mañana | D19: 489959 | E19: =9000+240977+24000 -> 273977 | F19: =D19-E19 -> 215982 | G19: =D19+D20 -> 925979 | H19: =E19+E20 -> 711397 | I19: =G19-H19 -> 214582
C20: Tarde | D20: 436020 | E20: =25000+147920+74500+160000+30000 -> 437420 | F20: =D20-E20 -> -1400
A21: Jueves | B21: 45911 | C21: Mañana | D21: 273492 | E21: 400643 | F21: =D21-E21 -> -127151 | G21: =D21+D22 -> 725469 | H21: =E21+E22 -> 775753 | I21: =G21-H21 -> -50284
C22: Tarde | D22: 451977 | E22: 375110 | F22: =D22-E22 -> 76867
A23: Viernes | B23: 45912 | C23: Mañana | D23: 348287 | E23: =9000+51400+39204+27651+98500 -> 225755 | F23: =D23-E23 -> 122532 | G23: =D23+D24 -> 780317 | H23: =E23+E24 -> 451655 | I23: =G23-H23 -> 328662
C24: Tarde | D24: 432030 | E24: =225900 -> 225900 | F24: =D24-E24 -> 206130
A25: Sabado | B25: 45913 | C25: Mañana | D25: 301847 | E25: =4500+22000 -> 26500 | F25: =D25-E25 -> 275347 | G25: =D25+D26 -> 624813 | H25: =E25+E26 -> 407688 | I25: =G25-H25 -> 217125
C26: Tarde | D26: 322966 | E26: =381188 -> 381188 | F26: =D26-E26 -> -58222
A27: Lunes | B27: 45915 | C27: Mañana | D27: 243252 | E27: =9000+12600+281632+20000 -> 323232 | F27: =D27-E27 -> -79980 | G27: =D27+D28 -> 703730 | H27: =E27+E28 -> 694732 | I27: =G27-H27 -> 8998
C28: Tarde | D28: 460478 | E28: =330000+41500 -> 371500 | F28: =D28-E28 -> 88978 | T28: Pago Sueldos
A29: Martes | B29: 45916 | C29: Mañana | D29: 300622 | E29: =9000+13000+19000+68498+60000+27000+8000 -> 204498 | F29: =D29-E29 -> 96124 | G29: =D29+D30 -> 833144 | H29: =E29+E30 -> 550854 | I29: =G29-H29 -> 282290 | T29: sabado normal
C30: Tarde | D30: 532522 | E30: =256356+90000 -> 346356 | F30: =D30-E30 -> 186166
A31: Miercoles | B31: 45917 | C31: Mañana | D31: 375392 | E31: =9000+9600+59240 -> 77840 | F31: =D31-E31 -> 297552 | G31: =D31+D32 -> 786494 | H31: =E31+E32 -> 331080 | I31: =G31-H31 -> 455414
C32: Tarde | D32: 411102 | E32: =253240 -> 253240 | F32: =D32-E32 -> 157862
A33: Jueves | B33: 45918 | C33: Mañana | D33: 326085 | E33: =9000+73000+203666+21039+72240+23400+30000 -> 432345 | F33: =D33-E33 -> -106260 | G33: =D33+D34 -> 787233 | H33: =E33+E34 -> 808202 | I33: =G33-H33 -> -20969
C34: Tarde | D34: 461148 | E34: =295857+80000 -> 375857 | F34: =D34-E34 -> 85291
A35: Viernes | B35: 45919 | C35: Mañana | D35: 494990 | E35: =9000+11400+191572+39204+46000 -> 297176 | F35: =D35-E35 -> 197814 | G35: =D35+D36 -> 933482 | H35: =E35+E36 -> 637476 | I35: =G35-H35 -> 296006
C36: Tarde | D36: 438492 | E36: =268100+27200+15000+30000 -> 340300 | F36: =D36-E36 -> 98192
A37: Sabado | B37: 45920 | C37: Mañana | D37: 288493 | E37: 4000 | F37: =D37-E37 -> 284493 | G37: =D37+D38 -> 537884 | H37: =E37+E38 -> 54000 | I37: =G37-H37 -> 483884
C38: Tarde | D38: 249391 | E38: 50000 | F38: =D38-E38 -> 199391
A39: Lunes | B39: 45922 | C39: Mañana | D39: 380219 | E39: =9000+12600+21039 -> 42639 | F39: =D39-E39 -> 337580 | G39: =D39+D40 -> 839364 | H39: =E39+E40 -> 217454 | I39: =G39-H39 -> 621910
C40: Tarde | D40: 459145 | E40: =174815 -> 174815 | F40: =D40-E40 -> 284330
...

Sheet Octubre_25
A1: Día | B1: fecha | C1: Turno | D1: Diaria | G1: Total
D2: Ingreso Diario | E2: Gasto Diario | F2: Ganancia Diaria | G2: Ingreso | H2: Gasto | I2: Ganancia
A3: Miércoles | B3: 45931 | C3: Mañana | D3: 477994 | E3: =9000+298448 -> 307448 | F3: =D3-E3 -> 170546 | G3: =D3+D4 -> 995653 | H3: =E3+E4 -> 543548 | I3: =G3-H3 -> 452105
C4: Tarde | D4: 517659 | E4: =71100+90000+65000+10000 -> 236100 | F4: =D4-E4 -> 281559
A5: Jueves | B5: 45932 | C5: Mañana | D5: 450563 | E5: =10000+283568+68084+55140 -> 416792 | F5: =D5-E5 -> 33771 | G5: =D5+D6 -> 857540 | H5: =E5+E6 -> 853292 | I5: =G5-H5 -> 4248
C6: Tarde | D6: 406977 | E6: =37400+15100+80000+8000+296000 -> 436500 | F6: =D6-E6 -> -29523
A7: Viernes | B7: 45933 | C7: Mañana | D7: 497416 | E7: =242459+10000+21300 -> 273759 | F7: =D7-E7 -> 223657 | G7: =D7+D8 -> 958345 | H7: =E7+E8 -> 535133 | I7: =G7-H7 -> 423212
C8: Tarde | D8: 460929 | E8: =43124+218250 -> 261374 | F8: =D8-E8 -> 199555
A9: Sabado | B9: 45934 | C9: Mañana | D9: 295126 | E9: =4500+25000 -> 29500 | F9: =D9-E9 -> 265626 | G9: =D9+D10 -> 550318 | H9: =E9+E10 -> 83500 | I9: =G9-H9 -> 466818
C10: tarde | D10: 255192 | E10: =20000+8000+26000 -> 54000 | F10: =D10-E10 -> 201192
A11: Lunes | B11: 45936 | C11: Mañana | D11: 325809 | E11: =298953+10000+13500 -> 322453 | F11: =D11-E11 -> 3356 | G11: =D11+D12 -> 787363 | H11: =E11+E12 -> 440964 | I11: =G11-H11 -> 346399
C12: Tarde | D12: 461554 | E12: =38500+74353+1717+3941 -> 118511 | F12: =D12-E12 -> 343043
A13: Martes | B13: 45937 | C13: Mañana | D13: 514435 | E13: =156262+10000+40000 -> 206262 | F13: =D13-E13 -> 308173 | G13: =D13+D14 -> 1044132 | H13: =E13+E14 -> 364172 | I13: =G13-H13 -> 679960
